Workbook
Name countryNameRange: [1]hiddenSheetForSFC!$A$1:$A$249
Name New: [1]New!$A$1:$A$4

Sheet Hoja3
A1: 39635 | B1: 215 70 R15 COOPER COBRA RAD G/T 97T (P) | C1: 56 | D1: AUCOP | E1: 1886.34 | F1: 1720.74 | G1: 1675.58
A2: HFLTBR25 | B2: 285/75 R24.5 DIRECCION (16) HH111 HIFLY | C2: 0 | D2: CAMHI | E2: 0 | F2: 0 | G2: 0
A3: 1054 | B3: 195 45 R15 78W YOKOHAMA S DRIVE AS01 | C3: 0 | D3: OFERP | E3: 1542.62 | F3: 1542.62 | G3: 1542.62
A4: 12050050 | B4: BOBINAS FORRAJERA DE 40 KG 2000 MTS C-15 | C4: 402 | D4: BOBIN | E4: 1078.68 | F4: 1078.68 | G4: 1078.68
A5: 3111850000 | B5: 185 65 R15 CONTINENTAL POWERCONTAC 2 88H | C5: 0 | D5: AUCON | E5: 1412.13 | F5: 1288.16 | G5: 1254.35
A6: 3112170000 | B6: 205 60 R16 CONTINENTAL POWERCONTACT 92H | C6: 0 | D6: AUCON | E6: 1959.69 | F6: 1787.65 | G6: 1740.73
A7: 3135140000 | B7: 195 65 R15 CONTINENTAL ULTRACONTAC 91H | C7: 192 | D7: AUCON | E7: 1591.18 | F7: 1451.5 | G7: 1413.4
A8: 3135180000 | B8: 195 55 R16 CONTINENTAL ULTRACONTAC 87V | C8: 114 | D8: AUCON | E8: 1974.67 | F8: 1801.31 | G8: 1754.03
A9: 3135220000 | B9: 215 55 R17 CONTINENTAL ULTRACONTACT 94V | C9: 0 | D9: OFERT | E9: 1780.62 | F9: 1780.62 | G9: 1780.62
A10: 3139810000 | B10: 225 45 R17 CONTINENTAL EXTREMECONT SPORT 91W | C10: 37 | D10: OFERT | E10: 1816.24 | F10: 1816.24 | G10: 1816.24
A11: 3506970000 | B11: 205 70 R16 CONTINENTAL PREMIUM CON2 97H | C11: 75 | D11: AUCON | E11: 2982.1 | F11: 2720.3 | G11: 2648.9
A12: 3526920000 | B12: 205 55 R16 91V CONTINENTAL PREMCONTACT 2 | C12: 0 | D12: AUCON | E12: 1624.99 | F12: 1482.33 | G12: 1443.43
A13: 3589240009 | B13: 195 65 R15 CONTINENTAL PREMIUMCONT 6 91H | C13: 78 | D13: AUCON | E13: 1745.93 | F13: 1592.66 | G13: 1550.85
A14: 3589250000 | B14: 205 55 R16 CONTINENTAL PREMICONTACT6 91V | C14: 42 | D14: AUCON | E14: 1697.91 | F14: 1548.86 | G14: 1508.2
... A58: 10000891 | B58: 11.00-20 CONVENCIONAL TORNEL T2900 | C58: 0 | D58: CAMOR | E58: 6412.04 | F58: 6247.35 | G58: 6027.76
A59: 100016BPH209A | B59: 10.00-16 F2 BROADPEAK H209A (10) AGRO | C59: 8 | D59: INBRO | E59: 2832.56 | F59: 2720.65 | G59: 2608.73
A60: 100016FRQH621 | B60: 10.00-16 F2 FORERUNNER QH621 (10) AGRO | C60: 30 | D60: AGERU | E60: 2234.32 | F60: 2146.04 | G60: 2057.76
A61: 100016FRQH622 | B61: 10.00-16 F2 AGRO FORERUNNER QH622 (10) | C61: 0 | D61: AGERU | E61: 2343.83 | F61: 2251.22 | G61: 2158.62
A62: 100016FRQH622SIN | B62: 10.00-16 F2 FORERUNNER 622 AGRO (10) | C62: 0 | D62: AGERU | E62: 2336.85 | F62: 2244.52 | G62: 2152.19
A63: 100065220 | B63: 185 60 R15 TORNEL DIRECCIONAL 84S | C63: 30 | D63: AUTOR | E63: 1137.61 | F63: 1037.74 | G63: 1010.5
A64: 100085450 | B64: 215 70 R15 TORNEL ASTRAL 97H | C64: 3 | D64: AUTOR | E64: 1509.86 | F64: 1377.31 | G64: 1341.16
A65: 10024160 | B65: 7.00-14 TORNEL(8) LT S/C T1300 | C65: 4 | D65: AUTOR | E65: 1752.56 | F65: 1598.71 | G65: 1556.75
A66: 10024170 | B66: 7.00-14 TORNEL (8) M/T S/C | C66: 0 | D66: AUTOR | E66: 1745.32 | F66: 1592.1 | G66: 1550.31
A67: 10025130 | B67: 7.00-15 T1300 S/C(6) TORNEL | C67: 14 | D67: AUTOR | E67: 2181.47 | F67: 1989.96 | G67: 1937.73
A68: 10025132 | B68: 7.00-15 TORNEL AMERICA MT(6) S/C | C68: 23 | D68: AUTOR | E68: 2254.78 | F68: 2056.83 | G68: 2002.85
A69: 10025140 | B69: 7.00-15 (6) TRAC 1700 CONVENCIONA TORNEL | C69: 0 | D69: CAMOR | E69: 0 | F69: 0 | G69: 0
A70: 10025150 | B70: 7.00-15 TORNEL T305 S/C CAMIONETA (6) | C70: 0 | D70: AUTOR | E70: 2020.3 | F70: 1842.94 | G70: 1794.57
A71: 10026290 | B71: 7.50-16 T1700 TORNEL(8) | C71: 0 | D71: OFERT | E71: 1860.21 | F71: 1860.21 | G71: 1860.21
A72: 10026300 | B72: 7.50-16 TORNEL 8 T305 S/C CAMIONETA(8) | C72: 0 | D72: AUTOR | E72: 2156.73 | F72: 1967.39 | G72: 1915.76
A73: 10026310 | B73: 7.50-16 TORNEL T-1300 S/C CAMIONETA(10) | C73: 0 | D73: AUTOR | E73: 2759.67 | F73: 2517.4 | G73: 2451.33
A74: 10026311 | B74: 7.50-16 TORNEL 1300 CAMIONETA (10) | C74: 0 | D74: AUTOR | E74: 2762.57 | F74: 2520.05 | G74: 2453.9
A75: 10026DD1 | B75: 7.50-16 TORNEL 14 T305 C/C CAMIONETA14) | C75: 0 | D75: AUTOR | E75: 1890.09 | F75: 1724.16 | G75: 1678.91
A76: 10027312 | B76: 7.50-17 TORNEL T1300 S/C CAMIONETA (10) | C76: 0 | D76: AUTOR | E76: 2891.04 | F76: 2637.24 | G76: 2568.02
A77: 10027321 | B77: 7.50-17 TRAC TORNEL CAMIONETA (10) | C77: 0 | D77: AUTOR | E77: 3011.29 | F77: 2746.93 | G77: 2674.83
A78: 10027331 | B78: 7.50-17 TORNEL JET TRAK MX C/C (10) | C78: 0 | D78: AUTOR | E78: 3354.39 | F78: 3059.91 | G78: 2979.6
A79: 10034389 | B79: 205 70 R14 TORNEL AT09 LN 97Q | C79: 35 | D79: AUTOR | E79: 1597.57 | F79: 1457.32 | G79: 1419.07
A80: 10035605 | B80: 235 75 R15 TORNEL AT-09 LB 104/101Q | C80: 0 | D80: OFERT | E80: 1796.22 | F80: 1796.22 | G80: 1796.22
A81: 10035607 | B81: 235 75 R15 TORNEL AT-09 LN 104/101Q | C81: 0 | D81: AUTOR | E81: 2106.8 | F81: 1921.85 | G81: 1871.41
A82: 10035863 | B82: 31X10.50 R15 TORNEL AT-09 109Q LT LN | C82: 4 | D82: AUTOR | E82: 2572.7 | F82: 2346.84 | G82: 2285.25
A83: 10036593 | B83: 235 70 R16 TORNEL AT09 LN 104/101Q | C83: 46 | D83: AUTOR | E83: 2298.55 | F83: 2096.76 | G83: 2041.73
...

Sheet Hoja1
F4: =NOW() -> 46267.398
A5: CLAVE | B5: DESCRIPCCIÓN | C5: PIEZAS | D5: CENTRAL | E5: MACRO | F5: ALMACEN DE SALIDA
A6: TR1426-001861
A7: 1757013TORTBO | B7: =IFERROR( VLOOKUP(A7,Hoja3!A:G,2,0),"0") -> 175 70 R13 TORNEL TURBO 82T | C7: 30 | D7: =IFERROR(VLOOKUP(A7,CENTRAL!A:G,3,0),0) -> 4678 | E7: =IFERROR(VLOOKUP(A7,MACRO!A:K,3,0),0) -> 0 | F7: CENTRAL
A8: 1855515BHHH11VT | B8: =IFERROR( VLOOKUP(A8,Hoja3!A:G,2,0),"0") -> 185 55 R15 BLACKHAWK HH11 VT 82V | C8: 8 | D8: =IFERROR(VLOOKUP(A8,CENTRAL!A:G,3,0),0) -> 264 | E8: =IFERROR(VLOOKUP(A8,MACRO!A:K,3,0),0) -> 765 | F8: CENTRAL
A9: 1856015BHHU71VT | B9: =IFERROR( VLOOKUP(A9,Hoja3!A:G,2,0),"0") -> 185 60 R15 BLACKHAWK HU71 VT 84H | C9: 4 | D9: =IFERROR(VLOOKUP(A9,CENTRAL!A:G,3,0),0) -> 5309 | E9: =IFERROR(VLOOKUP(A9,MACRO!A:K,3,0),0) -> 0 | F9: CENTRAL
A10: 1856514BHHH11VT | B10: =IFERROR( VLOOKUP(A10,Hoja3!A:G,2,0),"0") -> 185 65 R14 BLACKHAWK HH11 VT 86H | C10: 6 | D10: =IFERROR(VLOOKUP(A10,CENTRAL!A:G,3,0),0) -> 441 | E10: =IFERROR(VLOOKUP(A10,MACRO!A:K,3,0),0) -> 2443 | F10: CENTRAL
A11: 1956515BHHH11VT | B11: =IFERROR( VLOOKUP(A11,Hoja3!A:G,2,0),"0") -> 195 65 R15 BLACKHAWK HH11 VT 91H | C11: 2 | D11: =IFERROR(VLOOKUP(A11,CENTRAL!A:G,3,0),0) -> 58 | E11: =IFERROR(VLOOKUP(A11,MACRO!A:K,3,0),0) -> 1496 | F11: CENTRAL
A12: 1957014MEMR166 | B12: =IFERROR( VLOOKUP(A12,Hoja3!A:G,2,0),"0") -> 195 70 R14 MIRAGE MR-166 91H | C12: 4 | D12: =IFERROR(VLOOKUP(A12,CENTRAL!A:G,3,0),0) -> 327 | E12: =IFERROR(VLOOKUP(A12,MACRO!A:K,3,0),0) -> 352 | F12: CENTRAL
A13: 2055516BHHU01VT | B13: =IFERROR( VLOOKUP(A13,Hoja3!A:G,2,0),"0") -> 205 55 R16 BLACKHAWK HU01 VT 91W | C13: 10 | D13: =IFERROR(VLOOKUP(A13,CENTRAL!A:G,3,0),0) -> 589 | E13: =IFERROR(VLOOKUP(A13,MACRO!A:K,3,0),0) -> 493 | F13: CENTRAL
A14: 2056515BHHH11VT | B14: =IFERROR( VLOOKUP(A14,Hoja3!A:G,2,0),"0") -> 205 65 R15 BLACKHAWK HH11 VT 94H | C14: 6 | D14: =IFERROR(VLOOKUP(A14,CENTRAL!A:G,3,0),0) -> 280 | E14: =IFERROR(VLOOKUP(A14,MACRO!A:K,3,0),0) -> 507 | F14: CENTRAL
A15: 2057014BHHH01VT | B15: =IFERROR( VLOOKUP(A15,Hoja3!A:G,2,0),"0") -> 205 70 R14 BLACKHAWK HH01 VT 98T XL | C15: 4 | D15: =IFERROR(VLOOKUP(A15,CENTRAL!A:G,3,0),0) -> 705 | E15: =IFERROR(VLOOKUP(A15,MACRO!A:K,3,0),0) -> 1339 | F15: CENTRAL
A16: 115849 | B16: =IFERROR( VLOOKUP(A16,Hoja3!A:G,2,0),"0") -> 205 70 R16 COOPER EVOLUTION SPORT 97H | C16: 2 | D16: =IFERROR(VLOOKUP(A16,CENTRAL!A:G,3,0),0) -> 118 | E16: =IFERROR(VLOOKUP(A16,MACRO!A:K,3,0),0) -> 0 | F16: CENTRAL
A17: 2155516BHHU01VT | B17: =IFERROR( VLOOKUP(A17,Hoja3!A:G,2,0),"0") -> 215 55 R16 BLACKHAWK HU01 VT 97W XL | C17: 4 | D17: =IFERROR(VLOOKUP(A17,CENTRAL!A:G,3,0),0) -> 259 | E17: =IFERROR(VLOOKUP(A17,MACRO!A:K,3,0),0) -> 88 | F17: CENTRAL
A18: 2157015BHHH11VT | B18: =IFERROR( VLOOKUP(A18,Hoja3!A:G,2,0),"0") -> 215 70 R15 BLACKHAWK HH11 VT 98T | C18: 2 | D18: =IFERROR(VLOOKUP(A18,CENTRAL!A:G,3,0),0) -> 305 | E18: =IFERROR(VLOOKUP(A18,MACRO!A:K,3,0),0) -> 1632 | F18: CENTRAL
A19: 39635 | B19: =IFERROR( VLOOKUP(A19,Hoja3!A:G,2,0),"0") -> 215 70 R15 COOPER COBRA RAD G/T 97T (P) | C19: 4 | D19: =IFERROR(VLOOKUP(A19,CENTRAL!A:G,3,0),0) -> 91 | E19: =IFERROR(VLOOKUP(A19,MACRO!A:K,3,0),0) -> 0 | F19: CENTRAL
A20: 2157016BHAGILIVT | B20: =IFERROR( VLOOKUP(A20,Hoja3!A:G,2,0),"0") -> 215 70 R16 BLACKHAWK AGILITY SUV VT 100H | C20: 4 | D20: =IFERROR(VLOOKUP(A20,CENTRAL!A:G,3,0),0) -> 474 | E20: =IFERROR(VLOOKUP(A20,MACRO!A:K,3,0),0) -> 523 | F20: CENTRAL
A21: 2157016BHRIDGATV | B21: =IFERROR( VLOOKUP(A21,Hoja3!A:G,2,0),"0") -> 215 70 R16 BLACKHAWK RIDGE AT VT LB 100S | C21: 4 | D21: =IFERROR(VLOOKUP(A21,CENTRAL!A:G,3,0),0) -> 160 | E21: =IFERROR(VLOOKUP(A21,MACRO!A:K,3,0),0) -> 188 | F21: CENTRAL
A22: 2254518BHHU01VT | B22: =IFERROR( VLOOKUP(A22,Hoja3!A:G,2,0),"0") -> 225 45 R18 BLACKHAWK HU01 VT 95W XL | C22: 3 | D22: =IFERROR(VLOOKUP(A22,CENTRAL!A:G,3,0),0) -> 359 | E22: =IFERROR(VLOOKUP(A22,MACRO!A:K,3,0),0) -> 449 | F22: CENTRAL
A23: 2256017BHHT01VT | B23: =IFERROR( VLOOKUP(A23,Hoja3!A:G,2,0),"0") -> 225 60 R17 BLACKHAWK HISC HT01 VT 99H | C23: 6 | D23: =IFERROR(VLOOKUP(A23,CENTRAL!A:G,3,0),0) -> 135 | E23: =IFERROR(VLOOKUP(A23,MACRO!A:K,3,0),0) -> 339 | F23: CENTRAL
A24: 2256018BHAGILITY | B24: =IFERROR( VLOOKUP(A24,Hoja3!A:G,2,0),"0") -> 225 60 R18 BLACKHAWK AGILITY SUV VT 100H | C24: 4 | D24: =IFERROR(VLOOKUP(A24,CENTRAL!A:G,3,0),0) -> 101 | E24: =IFERROR(VLOOKUP(A24,MACRO!A:K,3,0),0) -> 443 | F24: CENTRAL
A25: 2354518BHHH11VT | B25: =IFERROR( VLOOKUP(A25,Hoja3!A:G,2,0),"0") -> 235 45 R18 BLACKHAWK HH11 VT 94V | C25: 6 | D25: =IFERROR(VLOOKUP(A25,CENTRAL!A:G,3,0),0) -> 229 | E25: =IFERROR(VLOOKUP(A25,MACRO!A:K,3,0),0) -> 550 | F25: CENTRAL
A26: 2355517BHAGILIVT | B26: =IFERROR( VLOOKUP(A26,Hoja3!A:G,2,0),"0") -> 235 55 R17 BLACKHAWK AGILITY SUV VT 99V | C26: 4 | D26: =IFERROR(VLOOKUP(A26,CENTRAL!A:G,3,0),0) -> 66 | E26: =IFERROR(VLOOKUP(A26,MACRO!A:K,3,0),0) -> 579 | F26: CENTRAL
A27: 2355519MEMRHP172 | B27: =IFERROR( VLOOKUP(A27,Hoja3!A:G,2,0),"0") -> 235 55 R19 MIRAGE MR-HP172 105V XL | C27: 4 | D27: =IFERROR(VLOOKUP(A27,CENTRAL!A:G,3,0),0) -> 27 | E27: =IFERROR(VLOOKUP(A27,MACRO!A:K,3,0),0) -> 42 | F27: CENTRAL
A28: 2357515KMO | B28: =IFERROR( VLOOKUP(A28,Hoja3!A:G,2,0),"0") -> 235 75 R15 KUMHO AT52 109T | C28: 2 | D28: =IFERROR(VLOOKUP(A28,CENTRAL!A:G,3,0),0) -> 66 | E28: =IFERROR(VLOOKUP(A28,MACRO!A:K,3,0),0) -> 0 | F28: CENTRAL
A29: 2457016BHHT01VT | B29: =IFERROR( VLOOKUP(A29,Hoja3!A:G,2,0),"0") -> 245 70 R16 BLACKHAWK HT01 VT 107S | C29: 4 | D29: =IFERROR(VLOOKUP(A29,CENTRAL!A:G,3,0),0) -> 42 | E29: =IFERROR(VLOOKUP(A29,MACRO!A:K,3,0),0) -> 327 | F29: CENTRAL
A30: 9036500 | B30: =IFERROR( VLOOKUP(A30,Hoja3!A:G,2,0),"0") -> 245 70 R16 COOPER EVOLUTION ATT 107T | C30: 6 | D30: =IFERROR(VLOOKUP(A30,CENTRAL!A:G,3,0),0) -> 80 | E30: =IFERROR(VLOOKUP(A30,MACRO!A:K,3,0),0) -> 0 | F30: CENTRAL
A31: 39602 | B31: =IFERROR( VLOOKUP(A31,Hoja3!A:G,2,0),"0") -> 295 50 R15 COOPER COBRA RAD G/T 105S (P) | C31: 2 | D31: =IFERROR(VLOOKUP(A31,CENTRAL!A:G,3,0),0) -> 38 | E31: =IFERROR(VLOOKUP(A31,MACRO!A:K,3,0),0) -> 0 | F31: CENTRAL
A32: 2955015TDIRASP90 | B32: =IFERROR( VLOOKUP(A32,Hoja3!A:G,2,0),"0") -> 295 50 R15 TDI TIRES RAUFFAN SP 900 105S | C32: 4 | D32: =IFERROR(VLOOKUP(A32,CENTRAL!A:G,3,0),0) -> 310 | E32: =IFERROR(VLOOKUP(A32,MACRO!A:K,3,0),0) -> 1641 | F32: CENTRAL
A33: 3054522GRROADFAS | B33: =IFERROR( VLOOKUP(A33,Hoja3!A:G,2,0),"0") -> 305 45 R22 GUTEROAD ROAD FASX 118W XL | C33: 4 | D33: =IFERROR(VLOOKUP(A33,CENTRAL!A:G,3,0),0) -> 144 | E33: =IFERROR(VLOOKUP(A33,MACRO!A:K,3,0),0) -> 0 | F33: CENTRAL
A34: 3312520MEMRMT172 | B34: =IFERROR( VLOOKUP(A34,Hoja3!A:G,2,0),"0") -> 33X12.50 R20 MIRAGE MR-MT172 114Q LT | C34: 4 | D34: =IFERROR(VLOOKUP(A34,CENTRAL!A:G,3,0),0) -> 71 | E34: =IFERROR(VLOOKUP(A34,MACRO!A:K,3,0),0) -> 151 | F34: CENTRAL
A35: TR1426-001862
A36: 1656014MEMR166 | B36: =IFERROR( VLOOKUP(A36,Hoja3!A:G,2,0),"0") -> 165 60 R14 MIRAGE MR-166 75H | C36: 18 | D36: =IFERROR(VLOOKUP(A36,CENTRAL!A:G,3,0),0) -> 1 | E36: =IFERROR(VLOOKUP(A36,MACRO!A:K,3,0),0) -> 52 | F36: MACRO
A37: 1756015BHHH11VT | B37: =IFERROR( VLOOKUP(A37,Hoja3!A:G,2,0),"0") -> 175 60 R15 BLACKHAW HH11 VT 81H | C37: 10 | D37: =IFERROR(VLOOKUP(A37,CENTRAL!A:G,3,0),0) -> 526 | E37: =IFERROR(VLOOKUP(A37,MACRO!A:K,3,0),0) -> 999 | F37: MACRO
A38: 1756514MEMR166 | B38: =IFERROR( VLOOKUP(A38,Hoja3!A:G,2,0),"0") -> 175 65 R14 MIRAGE MR-166 82H | C38: 20 | D38: =IFERROR(VLOOKUP(A38,CENTRAL!A:G,3,0),0) -> 0 | E38: =IFERROR(VLOOKUP(A38,MACRO!A:K,3,0),0) -> 699 | F38: MACRO
A39: 1757013MEMR166 | B39: =IFERROR( VLOOKUP(A39,Hoja3!A:G,2,0),"0") -> 175 70 R13 MIRAGE MR-166 82H | C39: 50 | D39: =IFERROR(VLOOKUP(A39,CENTRAL!A:G,3,0),0) -> 0 | E39: =IFERROR(VLOOKUP(A39,MACRO!A:K,3,0),0) -> 1388 | F39: MACRO
A40: 1856015BHHH11VT | B40: =IFERROR( VLOOKUP(A40,Hoja3!A:G,2,0),"0") -> 185 60 R15 BLACKHAWK HH11 VT 88H XL | C40: 14 | D40: =IFERROR(VLOOKUP(A40,CENTRAL!A:G,3,0),0) -> 0 | E40: =IFERROR(VLOOKUP(A40,MACRO!A:K,3,0),0) -> 4378 | F40: MACRO
A41: 1856015MEMR166 | B41: =IFERROR( VLOOKUP(A41,Hoja3!A:G,2,0),"0") -> 185 60 R15 MIRAGE MR-166 84H | C41: 100 | D41: =IFERROR(VLOOKUP(A41,CENTRAL!A:G,3,0),0) -> 0 | E41: =IFERROR(VLOOKUP(A41,MACRO!A:K,3,0),0) -> 3587 | F41: MACRO
A42: 1955015MEMR166 | B42: =IFERROR( VLOOKUP(A42,Hoja3!A:G,2,0),"0") -> 195 50 R15 MIRAGE MR-166 82V | C42: 6 | D42: =IFERROR(VLOOKUP(A42,CENTRAL!A:G,3,0),0) -> 1 | E42: =IFERROR(VLOOKUP(A42,MACRO!A:K,3,0),0) -> 378 | F42: MACRO
A43: 1955515MEMR166 | B43: =IFERROR( VLOOKUP(A43,Hoja3!A:G,2,0),"0") -> 195 55 R15 MIRAGE MR-166 85V | C43: 2 | D43: =IFERROR(VLOOKUP(A43,CENTRAL!A:G,3,0),0) -> 0 | E43: =IFERROR(VLOOKUP(A43,MACRO!A:K,3,0),0) -> 422 | F43: MACRO
...

Sheet CENTRAL
A1: 39635 | B1: 215 70 R15 COOPER COBRA RAD G/T 97T (P) | C1: 91 | D1: AUCOP | E1: Central | F1: 1897.99 | G1: 1731.37 | H1: 1685.93
A2: 12050050 | B2: BOBINAS FORRAJERA DE 40 KG 2000 MTS C-15 | C2: 1780 | D2: BOBIN | E2: Central | F2: 1078.35 | G2: 1078.35 | H2: 1078.35
A3: 3135140000 | B3: 195 65 R15 CONTINENTAL ULTRACONTAC 91H | C3: 275 | D3: AUCON | E3: Central | F3: 1577.24 | G3: 1438.77 | H3: 1401.01
A4: 3135180000 | B4: 195 55 R16 CONTINENTAL ULTRACONTAC 87V | C4: 86 | D4: AUCON | E4: Central | F4: 1974.67 | G4: 1801.31 | H4: 1754.03
A5: 3589240009 | B5: 195 65 R15 CONTINENTAL PREMIUMCONT 6 91H | C5: 20 | D5: AUCON | E5: Central | F5: 1745.93 | G5: 1592.66 | H5: 1550.85
A6: 4010120000 | B6: 235 75 R15 105S BARUM BRAVURIS AT | C6: 1 | D6: OFSIX | E6: Central | F6: 2369.41 | G6: 2287.21 | H6: 2215.29
A7: 4513490000 | B7: 205 70 R15 CONTINENTAL VANCONT AP 104R | C7: 1 | D7: AUCON | E7: Central | F7: 2794.19 | G7: 2548.89 | H7: 2481.99
A8: 4514640000 | B8: 215 85 R16 CONTINENTAL VANCONTAC AS 115/112Q | C8: 50 | D8: AUCON | E8: Central | F8: 3939.06 | G8: 3593.25 | H8: 3498.94
A9: 4514770000 | B9: 285 65 R16 CONTINENTAL VANCONTAC AS 131R | C9: 28 | D9: AUCON | E9: Central | F9: 5619.41 | G9: 5126.08 | H9: 4991.54
A10: 100085450 | B10: 215 70 R15 TORNEL ASTRAL 97H | C10: 1 | D10: AUTOR | E10: Central | F10: 1509.86 | G10: 1377.31 | H10: 1341.16
A11: 10025132 | B11: 7.00-15 TORNEL AMERICA MT(6) S/C | C11: 1 | D11: AUTOR | E11: Central | F11: 2254.78 | G11: 2056.83 | H11: 2002.85
A12: 10036593 | B12: 235 70 R16 TORNEL AT09 LN 104/101Q | C12: 15 | D12: AUTOR | E12: Central | F12: 2298.55 | G12: 2096.76 | H12: 2041.73
... A15: 10094240 | B15: 185 70 R14 TORNEL AMERICA AT-909 87S | C15: 1 | D15: AUTOR | E15: Central | F15: 1043.19 | G15: 951.6 | H15: 926.63
A16: 10094310T | B16: 195 70 R14 TORNEL AMERICA AT909 90T | C16: 1 | D16: OFERT | E16: Central | F16: 846.56 | G16: 846.56 | H16: 846.56
A17: 108805 | B17: 205 55 R16 GOODYEAR EAGLE SPORT 2 91V | C17: 140 | D17: AUGOO | E17: Central | F17: 1575.8 | G17: 1437.46 | H17: 1399.73
A18: 109941 | B18: 235 55 R18 GOODYEAR ASSURAN FINESSE 100H | C18: 81 | D18: AUGOO | E18: Central | F18: 2512.26 | G18: 2291.71 | H18: 2231.56
A19: 10A54223 | B19: 185 60 R14 TORNEL REAL 82H | C19: 38 | D19: AUTOR | E19: Central | F19: 1078.56 | G19: 983.88 | H19: 958.05
A20: 10A55343 | B20: 195 50 R15 TORNEL REAL 81V | C20: 58 | D20: AUTOR | E20: Central | F20: 1217.54 | G20: 1110.66 | H20: 1081.51
A21: 10A55353 | B21: 195 55 R15 TORNEL REAL 84V | C21: 19 | D21: AUTOR | E21: Central | F21: 1197.88 | G21: 1092.72 | H21: 1064.04
A22: 10A56440 | B22: 215 65 R16 TORNEL REAL 96H | C22: 4 | D22: AUTOR | E22: Central | F22: 1568.76 | G22: 1431.04 | H22: 1393.48
A23: 110325 | B23: 185 65 R14 GOODYEAR ASSURAN MAXLIFE 86H | C23: 1 | D23: AUGOO | E23: Central | F23: 1483.13 | G23: 1352.93 | H23: 1317.42
A24: 110540 | B24: 185 70 R13 GOODYEAR ASSURANCE MAXLIF 86T | C24: 93 | D24: AUGOO | E24: Central | F24: 1383.88 | G24: 1262.39 | H24: 1229.25
A25: 111381 | B25: 235 75 R15 GOODYEAR WORKHORSE AT 109S | C25: 49 | D25: AUGOO | E25: Central | F25: 2701.34 | G25: 2464.19 | H25: 2399.52
A26: 11225DSDSR768 | B26: 11R22.5 TRACCION DOUBLESTAR DSR768 (16) | C26: 10 | D26: OFERT | E26: Central | F26: 4128.82 | G26: 4128.82 | H26: 4128.82
A27: 11245AEHF82618C | B27: 11R24.5 MINERA AGATE HF826 (18) | C27: 56 | D27: OFERT | E27: Central | F27: 3235.72 | G27: 3235.72 | H27: 3235.72
A28: 11245MEMG82618C | B28: 11R24.5 MINERA MIRAGE MG826 (18) | C28: 2 | D28: OFECA | E28: Central | F28: 3642.02 | G28: 3545.76 | H28: 3449.49
A29: 115809 | B29: 255 70 R16 COOPER EVOLUTION ATT 111T | C29: 12 | D29: AUCOP | E29: Central | F29: 2779.23 | G29: 2535.24 | H29: 2468.7
A30: 115849 | B30: 205 70 R16 COOPER EVOLUTION SPORT 97H | C30: 118 | D30: AUCOP | E30: Central | F30: 1729.42 | G30: 1577.59 | H30: 1536.19
A31: 115852 | B31: 235 60 R17 COOPER EVOLUTION SPORT 102H | C31: 1 | D31: AUCOP | E31: Central | F31: 1932.13 | G31: 1762.51 | H31: 1716.25
A32: 13-MT-ZW33125020 | B32: 33X12.50 R20 ZWARTHZ ARIZONA MT 114Q LT | C32: 1 | D32: AUZTZ | E32: Central | F32: 2826.77 | G32: 2578.61 | H32: 2510.93
A33: 142448 | B33: 265 70 R17 GOODYEAR WORKHORSE AT2 LB 123R | C33: 403 | D33: AUGOO | E33: Central | F33: 3171.34 | G33: 2892.93 | H33: 2817
A34: 14705100 | B34: 11R22.5 DIRECCION FIRESTONE FS591 (16) | C34: 99 | D34: CAMNE | E34: Central | F34: 7900.3 | G34: 7900.3 | H34: 7900.3
A35: 14706100 | B35: 11R24.5 DIRECCION FIRESTONE FS591 (16) | C35: 68 | D35: CAMNE | E35: Central | F35: 8143.14 | G35: 8143.14 | H35: 8143.14
A36: 15409560000 | B36: 185 70 R14 BARUM BRAVURIS 5HM 88H | C36: 1 | D36: OFERP | E36: Central | F36: 951.06 | G36: 951.06 | H36: 951.06
A37: 15409620000 | B37: 175 65 R14 BARUM BRAVURIS 5HM 82T | C37: 3 | D37: OFERP | E37: Central | F37: 863.97 | G37: 863.97 | H37: 863.97
A38: 15409670000 | B38: 185 60 R14 BARUM BRAVURIS 5HM 82H | C38: 1 | D38: OFERP | E38: Central | F38: 999.54 | G38: 999.54 | H38: 999.54
A39: 15508610000 | B39: 205 55 R16 CONTINENTAL POWERCONTACT2 91V | C39: 141 | D39: AUCON | E39: Central | F39: 1537.11 | G39: 1402.17 | H39: 1365.37
A40: 1557013BHHH11VT | B40: 155 70 R13 BLACKHAWK HH11 VT 75T | C40: 376 | D40: OFERT | E40: Central | F40: 443.78 | G40: 443.78 | H40: 443.78
A41: 1557013COMPBLAHP | B41: 155 70 R13 COMPASAL BLAZER HP 75T | C41: 1 | D41: OFERP | E41: Central | F41: 450.59 | G41: 450.59 | H41: 450.59
A42: 1557013KNHD918 | B42: 155 70 R13 KAPSEN HD918 75T (4) | C42: 1 | D42: AUKAP | E42: Central | F42: 572.8 | G42: 522.51 | H42: 508.8
...

Sheet MACRO
A1: 100016FRQH621 | B1: 10.00-16 F2 FORERUNNER QH621 (10) AGRO | C1: 7 | D1: AGERU | E1: MACRO CEDIS | F1: 2234.32 | G1: 2146.04 | H1: 2057.76
A2: 1115BPH661 | B2: 11L15 F3 BROADPEAK H661 IND (12) | C2: 20 | D2: INBRO | E2: MACRO CEDIS | F2: 1852.41 | G2: 1779.22 | H2: 1706.03
A3: 1115BPH663 | B3: 11L15 I-1 BROADPEAK H663 (12) AGRO | C3: 28 | D3: AGBRO | E3: MACRO CEDIS | F3: 1572.86 | G3: 1510.71 | H3: 1448.57
A4: 11225AMAD507 | B4: 11R22.5 TRACCION AMULET AD507 (16) | C4: 1 | D4: CAMET | E4: MACRO CEDIS | F4: 4798.46 | G4: 4675.21 | H4: 4510.88
A5: 11225AMAF50818C | B5: 11R22.5 DIRECCION AMULET AF508 (18) | C5: 574 | D5: CAMET | E5: MACRO CEDIS | F5: 4349.18 | G5: 4237.47 | H5: 4088.53
A6: 11225BHBDL71 | B6: 11R22.5 TRACCION BLACKHAWK BDL71 (16) | C6: 221 | D6: CAMBK | E6: MACRO CEDIS | F6: 4424.67 | G6: 4311.02 | H6: 4159.49
A7: 11225BHBFR55FST | B7: 11R22.5 DIRECCION BLACKHAWK BFR55-FST (16) | C7: 140 | D7: CAMBK | E7: MACRO CEDIS | F7: 3692.72 | G7: 3597.87 | H7: 3471.41
A8: 11225HRY77918C | B8: 11R22.5 MINERA HAPPY ROAD Y779 (18) | C8: 293 | D8: OFECA | E8: MACRO CEDIS | F8: 3604.22 | G8: 3508.96 | H8: 3413.69
A9: 11225MEMG11118C | B9: 11R22.5 DIRECCION MIRAGE MG111 (18) | C9: 1514 | D9: OFECA | E9: MACRO CEDIS | F9: 3011.09 | G9: 2931.51 | H9: 2851.92
A10: 11225MEMG31218C | B10: 11R22.5 TRACCION MIRAGE MG312 (18) | C10: 316 | D10: CAMMR | E10: MACRO CEDIS | F10: 3439.44 | G10: 3351.1 | H10: 3233.31
A11: 11225MEMG70218C | B11: 11R22.5 MIXTA MIRAGE MG702 (18) | C11: 38 | D11: OFECA | E11: MACRO CEDIS | F11: 3454.55 | G11: 3363.24 | H11: 3271.93
A12: 11225STTITANTR18 | B12: 11R22.5 TRACCION SURETRAC TITAN TRACK (18) | C12: 40 | D12: CAMSC | E12: MACRO CEDIS | F12: 3474.53 | G12: 3385.29 | H12: 3266.3
... A531: FRON-2EFW061F | B531: 225 55 R17 FRONWAY EURUS 08 101W XL | C531: 2 | D531: OFERP | E531: MACRO CEDIS | F531: 1057.61 | G531: 1057.61 | H531: 1057.61
